<?xml version="1.0"?>

<robot name="five_dof_robot">
  <link name="base_link">
    <inertial>
      <origin xyz="0 0 0" rpy="0 0 0" />
      <mass value="5.0" />
      <inertia ixx="0.1" ixy="0.0" ixz="0.0" iyy="0.1" iyz="0.0" izz="0.1" />
    </inertial>
  </link>

  <link name="link_1">
    <visual>
      <geometry>
        <cylinder length="0.5" radius="0.05" />
      </geometry>
      <origin xyz="0 0 0.25" rpy="0 0 0" />
    </visual>
  </link>

  <joint name="joint_1" type="revolute">
    <parent link="base_link" />
    <child link="link_1" />
    <origin xyz="0 0 0" rpy="0 0 0" />
    <axis xyz="0 0 1" />
    <limit lower="-1.57" upper="1.57" effort="10" velocity="1.0" />
  </joint>

  <link name="link_2">
    <visual>
      <geometry>
        <box size="0.5 0.1 0.1" />
      </geometry>
      <origin xyz="0.25 0 0" rpy="0 0 0" />
    </visual>
  </link>

  <joint name="joint_2" type="prismatic">
    <parent link="link_1" />
    <child link="link_2" />
    <origin xyz="0 0 0.5" rpy="0 0 0" />
    <axis xyz="1 0 0" />
    <limit lower="0.0" upper="0.5" effort="10" velocity="0.5" />
  </joint>

  <link name="link_3">
    <visual>
      <geometry>
        <cylinder length="0.5" radius="0.05" />
      </geometry>
      <origin xyz="0 0 0.25" rpy="0 0 0" />
    </visual>
  </link>

  <joint name="joint_3" type="revolute">
    <parent link="link_2" />
    <child link="link_3" />
    <origin xyz="0.5 0 0" rpy="0 0 0" />
    <axis xyz="0 1 0" />
    <limit lower="-1.57" upper="1.57" effort="10" velocity="1.0" />
  </joint>

  <link name="link_4">
    <visual>
      <geometry>
        <box size="0.5 0.1 0.1" />
      </geometry>
      <origin xyz="0.25 0 0" rpy="0 0 0" />
    </visual>
  </link>

  <joint name="joint_4" type="prismatic">
    <parent link="link_3" />
    <child link="link_4" />
    <origin xyz="0 0 0.5" rpy="0 0 0" />
    <axis xyz="0 0 1" />
    <limit lower="0.0" upper="0.5" effort="10" velocity="0.5" />
  </joint>

  <link name="link_5">
    <visual>
      <geometry>
        <cylinder length="0.5" radius="0.05" />
      </geometry>
      <origin xyz="0 0 0.25" rpy="0 0 0" />
    </visual>
  </link>

  <joint name="joint_5" type="revolute">
    <parent link="link_4" />
    <child link="link_5" />
    <origin xyz="0.5 0 0" rpy="0 0 0" />
    <axis xyz="1 0 0" />
    <limit lower="-1.57" upper="1.57" effort="10" velocity="1.0" />
  </joint>
</robot>

